package cn.feng.thinkInJava.a7_4_异常.exceptions.a12_06_02.重新抛出异常;

//: exceptions/Rethrowing.java
// Demonstrating fillInStackTrace()
//重新抛出异常
public class Rethrowing {

    public static void f() throws Exception {
        System.out.println("originating the exception in f()");
        throw new Exception("thrown from f()");
    }
    public static void g() throws Exception {
        try {
            f();
        } catch (Exception e) {
            System.out.println("Inside g(),e.printStackTrace()");
            e.printStackTrace(System.out);
            throw e;
        }
    }
    public static void h() throws Exception {
        try {
            f();
        } catch (Exception e) {
            System.out.println("Inside h(),e.printStackTrace()");
            e.printStackTrace(System.out);
            throw (Exception) e.fillInStackTrace();//通过调用fillInStackTrace()方法将返回一个Throwable对象,它是通过当前调用栈信息填入远来那个异常对象而建立的
        }
    }
    public static void main(String[] args) {
        try {
            g();
        } catch (Exception e) {
            System.out.println("main: printStackTrace()");
            e.printStackTrace(System.out);
        }
        try {
            h();
        } catch (Exception e) {
            System.out.println("main: printStackTrace()");
            e.printStackTrace(System.out);
        }
    }
} /* Output:
originating the exception in f()
Inside g(),e.printStackTrace()
java.lang.Exception: thrown from f()
        at Rethrowing.f(Rethrowing.java:7)
        at Rethrowing.g(Rethrowing.java:11)
        at Rethrowing.main(Rethrowing.java:29)
main: printStackTrace()
java.lang.Exception: thrown from f()
        at Rethrowing.f(Rethrowing.java:7)
        at Rethrowing.g(Rethrowing.java:11)
        at Rethrowing.main(Rethrowing.java:29)
originating the exception in f()
Inside h(),e.printStackTrace()
java.lang.Exception: thrown from f()
        at Rethrowing.f(Rethrowing.java:7)
        at Rethrowing.h(Rethrowing.java:20)
        at Rethrowing.main(Rethrowing.java:35)
main: printStackTrace()
java.lang.Exception: thrown from f()
        at Rethrowing.h(Rethrowing.java:24)
        at Rethrowing.main(Rethrowing.java:35)
*///:~
